<?xml version="1.0"?>
<robot name="unicycle">
  
	<link name="base_link">
    <visual>
      <geometry>
        <cylinder length="0.5" radius="0.02"/>
      </geometry>
			<origin rpy="0 0 0" xyz="0 0 0"/>
    </visual>
    <collision>
      <geometry>
        <cylinder length="0.5" radius="0.02"/>
      </geometry>
			<origin rpy="0 0 0" xyz="0 0 0.5"/>
    </collision>
 		<inertial>
			<mass value="2"/>
			<inertia ixx="1e-3" ixy="0.0" ixz="0.0" iyy="1e-3" iyz="0.0" izz="1e-3"/>
		</inertial> 
	</link>
	
	<link name="wheel">
    <visual>
      <geometry>
        <cylinder length="0.05" radius="0.25"/>
      </geometry>
			<origin rpy="1.57075 0 0" xyz="0 0 0"/>
    </visual>
    <collision>
      <geometry>
        <cylinder length="0.05" radius="0.25"/>
      </geometry>
			<origin rpy="1.57075 0 0" xyz="0 0 0"/>
    </collision>
 		<inertial>
			<mass value="1"/>
			<inertia ixx="1e-3" ixy="0.0" ixz="0.0" iyy="1e-3" iyz="0.0" izz="1e-3"/>
		</inertial> 
  </link>
	<joint name="base_link_to_wheel" type="continuous">
		<parent link="base_link"/>
		<child link="wheel"/>
		<axis xyz="0 1 0"/>
		<origin xyz="0 0 -0.25"/>
	</joint>

	<link name="seat">
		<visual>
			<geometry>
				<box size="0.1 0.1 0.1"/>
			</geometry>
			<origin rpy="0 0 0" xyz="0 0 0.05"/>
		</visual>
		<collision>
			<geometry>
				<box size="0.1 0.1 0.1"/>
			</geometry>
			<origin rpy="0 0 0" xyz="0 0 0.05"/>
		</collision>
		<inertial>
			<mass value="1"/>
			<inertia ixx="1e-3" ixy="0.0" ixz="0.0" iyy="1e-3" iyz="0.0" izz="1e-3"/>
		</inertial> 
	</link>
	<joint name="base_link_to_seat" type="fixed">
		<parent link="base_link"/>
		<child link="seat"/>
		<origin xyz="0 0 0.25"/>
	</joint>

	<!-- Gazebo plugin for ROS Control -->
  <gazebo>
    <plugin name="gazebo_ros_control" filename="libgazebo_ros_control.so">
      <robotNamespace>/</robotNamespace>
    </plugin>
  </gazebo>

</robot>
